Workbook

Sheet Summary
A1: PIPELINE OVERVIEW
A2: Metric | B2: Value
A3: Total Scraped Profiles | B3: =COUNTA(Profiles!A:A)-1 -> 609
A4: Total Classified | B4: =COUNTA('Classified Leads'!A:A)-1 -> 285
A5: Unclassified (Pending) | B5: =MAX(0,(COUNTA(Profiles!A:A)-1)-(COUNTA('Classified Leads'!A:A)-1)) -> 324
A6: Classification Progress % | B6: =IF(COUNTA(Profiles!A:A)-1>0,(COUNTA('Classified Leads'!A:A)-1)/(COUNTA(Profiles!A:A)-1),0) -> 0.4679803
A7: Total Relevant Leads | B7: =COUNTA('Relevant Leads'!A:A)-1 -> 92
A8: Relevance Rate % | B8: =IF(COUNTA('Classified Leads'!A:A)-1>0,(COUNTA('Relevant Leads'!A:A)-1)/(COUNTA('Classified Leads'!A:A)-1),0) -> 0.32280702
A10: CLASSIFICATION BREAKDOWN
A11: Classification | B11: Count | C11: % of Total
A12: Collector | B12: =COUNTIF('Classified Leads'!R:R,"collector") -> 46 | C12: =IF(B4>0,B12/B4,0) -> 0.16140351
A13: Dealer | B13: =COUNTIF('Classified Leads'!R:R,"dealer") -> 27 | C13: =IF(B4>0,B13/B4,0) -> 0.094736842
A14: Enthusiast | B14: =COUNTIF('Classified Leads'!R:R,"enthusiast") -> 19 | C14: =IF(B4>0,B14/B4,0) -> 0.066666667
A15: Media/Influencer | B15: =COUNTIF('Classified Leads'!R:R,"media")+COUNTIF('Classified Leads'!R:R,"influencer") -> 0 | C15: =IF(B4>0,B15/B4,0) -> 0
A16: Irrelevant | B16: =COUNTIF('Classified Leads'!R:R,"irrelevant") -> 82 | C16: =IF(B4>0,B16/B4,0) -> 0.2877193
A17: Error/Unknown | B17: =COUNTIF('Classified Leads'!R:R,"error")+COUNTIF('Classified Leads'!R:R,"unknown") -> 111 | C17: =IF(B4>0,B17/B4,0) -> 0.38947368
A19: PROFILE STATISTICS
A20: Metric | B20: Value
A21: Avg Follower Count | B21: =IF(COUNTA(Profiles!A:A)>1,ROUND(AVERAGE(Profiles!E2:E1000),0),0) -> 5710
A22: Median Follower Count | B22: =IF(COUNTA(Profiles!A:A)>1,ROUND(MEDIAN(Profiles!E2:E1000),0),0) -> 680
A23: Avg Post Count | B23: =IF(COUNTA(Profiles!A:A)>1,ROUND(AVERAGE(Profiles!G2:G1000),0),0) -> 415
A24: Verified Accounts | B24: =COUNTIF(Profiles!H:H,TRUE) -> 50
A25: Business Accounts | B25: =COUNTIF(Profiles!I:I,TRUE) -> 119
A26: Has Email in Bio | B26: =COUNTIFS(Profiles!M2:M1000,"<>") -> 11
A27: Has Phone in Bio | B27: =COUNTIFS(Profiles!N2:N1000,"<>") -> 16
A28: Has External URL | B28: =COUNTIFS(Profiles!K2:K1000,"<>") -> 184
A30: RELEVANT LEADS QUALITY
A31: Metric | B31: Value
A32: Avg Priority Score | B32: =IF(COUNTA('Relevant Leads'!A:A)>1,ROUND(AVERAGE('Relevant Leads'!D2:D1000),1),0) -> 6
A33: Max Priority Score | B33: =IF(COUNTA('Relevant Leads'!A:A)>1,MAX('Relevant Leads'!D2:D1000),0) -> 10
A34: High Priority (Score >= 7) | B34: =COUNTIFS('Relevant Leads'!D2:D1000,">="&7) -> 42
A35: Medium Priority (4-6.9) | B35: =COUNTIFS('Relevant Leads'!D2:D1000,">="&4,'Relevant Leads'!D2:D1000,"<"&7) -> 30
A36: Low Priority (< 4) | B36: =COUNTIFS('Relevant Leads'!D2:D1000,"<"&4,'Relevant Leads'!D2:D1000,">"&0) -> 20
A38: NET WORTH DISTRIBUTION
A39: Tier | B39: Count
A40: Ultra High Net Worth | B40: =COUNTIF('Classified Leads'!X:X,"*ultra*") -> 2
A41: High Net Worth | B41: =COUNTIF('Classified Leads'!X:X,"*high*")-COUNTIF('Classified Leads'!X:X,"*ultra*") -> 43
A42: Medium Net Worth | B42: =COUNTIF('Classified Leads'!X:X,"*medium*")+COUNTIF('Classified Leads'!X:X,"*moderate*") -> 0
A43: Unknown/Other | B43: =MAX(0,B4-B39-B40-B41) -> #VALUE!
A45: CONTACTABLE RELEVANT LEADS
...

Sheet Sheet1
A1: doc.txt | B1: Individual Collector | C1: Collector/Page | D1: Dealer | E1: Media | F1: Collector's Club | G1: Auction House | H1: Celebrities | I1: Other Luxury Goods | J1: Designer
A2: instagram.com/roni_m_29 | B2: https://www.instagram.com/jc_jil/ | C2: https://www.instagram.com/loupethis/ | D2: https://www.instagram.com/watch_investor/ | E2: https://www.instagram.com/hodinkee/ | F2: https://www.instagram.com/shanghaiwatchgang/ | G2: https://www.instagram.com/polyauctionhk/ | H2: https://www.instagram.com/sunnyboyyy/ | I2: https://www.instagram.com/supercarownerscircle/ | J2: https://www.instagram.com/sin_takizawa/
A3: instagram.com/bader_belselah | B3: https://www.instagram.com/a.dose.of.time/ | C3: https://www.instagram.com/amsterdamvintagewatches/ | D3: https://www.instagram.com/dauri.club/ | E3: https://www.instagram.com/monochromewatches/ | G3: https://www.instagram.com/bonhamswatches/ | H3: https://www.instagram.com/willpan23/ | I3: https://www.instagram.com/classicdriver/ | J3: https://www.instagram.com/nari_x_x_x_/
A4: instagram.com/markchodotcom | B4: https://www.instagram.com/jessicajjos/ | C4: https://www.instagram.com/watchanish/ | D4: https://www.instagram.com/1224_com/ | E4: https://www.instagram.com/watchonista/ | G4: https://www.instagram.com/christieswatches/ | I4: https://www.instagram.com/yachtcharterfleet/ | J4: https://www.instagram.com/rhuigi/
A5: instagram.com/indigo.8 | B5: https://www.instagram.com/paulabatinas/ | C5: https://www.instagram.com/santa_laura/ | D5: https://www.instagram.com/precious_time_now/ | E5: https://www.instagram.com/watchanalytics/ | G5: https://www.instagram.com/phillipswatches/ | I5: https://www.instagram.com/robbreport/
A6: instagram.com/watchdulum | B6: https://www.instagram.com/fedtan/ | C6: https://www.instagram.com/horology_ancienne/ | D6: https://www.instagram.com/yuriy_grekov74/ | E6: instagram.com/watch_the_f_out | G6: https://www.instagram.com/sothebyswatches/
A7: instagram.com/watchesa85 | B7: https://www.instagram.com/kpee/ | C7: https://www.instagram.com/patekgallery/ | D7: https://www.instagram.com/watchgirloffduty/ | E7: https://www.instagram.com/danblink
A8: instagram.com/bubbasteph | B8: https://www.instagram.com/lunglungthun/ | C8: https://www.instagram.com/horology_ancienne | D8: https://www.instagram.com/worldlywatches/
A9: instagram.com/luxecoffer | B9: https://www.instagram.com/timk1019/ | C9: https://www.instagram.com/matthiashaha | D9: https://www.instagram.com/watchand/
A10: instagram.com/champsg | B10: https://www.instagram.com/a_zhangerator/ | C10: https://www.instagram.com/watches_gmk | D10: https://www.instagram.com/dtimepieces.sg/
A11: instagram.com/fremstar | B11: https://www.instagram.com/johnson.collection/ | C11: https://www.instagram.com/watchfalcon | D11: https://www.instagram.com/mikenouveau/
A12: instagram.com/watchjabs | C12: https://www.instagram.com/cuuhu3888 | D12: https://www.instagram.com/eastcrown_japan/
A13: instagram.com/thewrongwrist | C13: https://www.instagram.com/wristspeaker/ | D13: https://www.instagram.com/woohoo_time/
A14: instagram.com/hairdude | C14: instagram.com/zachattack__25 | D14: https://www.instagram.com/watchnerdco/
A15: instagram.com/watch_the_f_out | D15: https://www.instagram.com/oliverandclarke/
A16: instagram.com/bangkokwrist | D16: https://www.instagram.com/kinsmen_ltd/
A17: instagram.com/journehutong | D17: https://www.instagram.com/shoyo_k/
A18: instagram.com/tom.chng
A19: instagram.com/battermaker
A20: instagram.com/faizul.ridzuan
A21: instagram.com/dens.watchvault
A22: instagram.com/watch.jelly
A23: instagram.com/luckymanzano
A24: instagram.com/zachattack__25
A25: instagram.com/johnson.collection
A26: instagram.com/danblink
A27: instagram.com/horology_ancienne
A28: instagram.com/masato.official
A29: instagram.com/matthiashaha
... A71: https://www.instagram.com/dr_audemars/

Sheet Profiles
A1: username | B1: platform | C1: full_name | D1: bio | E1: follower_count | F1: following_count | G1: post_count | H1: is_verified | I1: is_business | J1: business_category | K1: external_url | L1: profile_pic_url | M1: email_in_bio | N1: phone_in_bio | O1: engagement_rate | P1: recent_captions | Q1: hashtags | R1: mentions | S1: recent_post_urls | T1: recent_post_likes | U1: recent_post_comments | V1: recent_post_dates | W1: recent_post_locations | X1: recent_post_types | Y1: image_urls | Z1: video_urls | AA1: avg_likes | AB1: avg_comments | AC1: scrape_date | AD1: seed_account | AE1: seed_type | AF1: profile_url
A2: gunnertachejose | B2: instagram | C2: Jose R. Perez | E2: 571 | F2: 3536 | G2: 51 | H2: FALSE | I2: FALSE | L2: https://scontent-iad3-2.cdninstagram.com/v/t51.82787-19/568070790_18512543902068336_3998894716886781335_n.jpg?stp=dst-jpg_e0_s150x150_tt6&efg=eyJ2ZW5jb2RlX3RhZyI6InByb2ZpbGVfcGljLmRqYW5nby45NjAuYzIifQ&_nc_ht=scontent-iad3-2.cdninstagram.com&_nc_cat=100&_nc_oc=Q6cZ2QF4_ne5iN-IAFuxkpnTotn60cdpP-DocHD14HxlgKMganw4uoJ0AgT7c8CPZ9tZnEg&_nc_ohc=TnAiRTOqwpQQ7kNvwFk0gVe&_nc_gid=1Uz9GzkoOm5RERNhmxMMFQ&edm=AOQ1c0wBAAAA&ccb=7-5&oh=00_AfyKuub8ZKHvC1wlM6DXc3IKxJXkcvD2bTRwVRrDqglyoA&oe=69BD9C69&_nc_sid=8b3546 | O2: 0.035 | P2: 10 watches from Puerto Rico; Philippines; France;Switzerland; Rusia; China; England; Singapore; Australia; United States. 1 picture | S2: https://instagram.com/p/DUPQf9fEc-X, https://instagram.com/p/DUOGvx_kRu3, https://instagram.com/p/DUL0HjhERP-, https://instagram.com/p/DULmMPUEVcx, https://instagram.com/p/DULl0lokdBp, https://instagram.com/p/DULI1J6EY0B, https://instagram.com/p/DUI6b_ekYn7, https://instagram.com/p/DUIz6RDkaau, https://instagram.com/p/DUIzq0iEQFY, https://instagram.com/p/DUIyqNokdWs, https://instagram.com/p/DUIuhRlEUBI, https://instagram.com/p/DUGnElDEfGb | T2: 24, 20, 25, 20, 13, 22, 12, 25, 8, 7, 11, 43 | U2: 2, 2, 1, 0, 0, 0, 0, 0, 0, 0, 3, 2 | V2: 2026-02-02, 2026-02-01, 2026-01-31, 2026-01-31, 2026-01-31, 2026-01-31, 2026-01-30, 2026-01-30, 2026-01-30, 2026-01-30, 2026-01-30, 2026-01-29 | X2: Image, Video, Video, Image, Image, Image, Video, Image, Image, Video, Video, Image | Y2: https://scontent-iad3-2.cdninstagram.com/v/t51.82787-15/626473210_18530467810068336_2591620040173073744_n.heic?stp=dst-jpg_e15_fr_p1080x1080_tt6&_nc_ht=scontent-iad3-2.cdninstagram.com&_nc_cat=100&_nc_oc=Q6cZ2QF4_ne5iN-IAFuxkpnTotn60cdpP-DocHD14HxlgKMganw4uoJ0AgT7c8CPZ9tZnEg&_nc_ohc=BddgG_ocAXcQ7kNvwETAqdf&_nc_gid=1Uz9GzkoOm5RERNhmxMMFQ&edm=AOQ1c0wBAAAA&ccb=7-5&ig_cache_key=MzgyMzM0NzE3MzcyODMwOTE0Mw%3D%3D.3-ccb7-5&oh=00_AfwReCybVhbiZ7UHNNm9YDEMw34yFubhUfxs7mnybx60sA&oe=69BD9A3B&_nc_sid=8b3546, https://scontent-iad3-2.cdninstagram.com/v/t51.82787-15/624549240_18530129350068336_2101175656524860850_n.heic?stp=dst-jpg_e35_s1080x1080_sh0.08_tt6&_nc_ht=scontent-iad3-2.cdninstagram.com&_nc_cat=100&_nc_oc=Q6cZ2QF4_ne5iN-IAFuxkpnTotn60cdpP-DocHD14HxlgKMganw4uoJ0AgT7c8CPZ9tZnEg&_nc_ohc=uKpXynLFi9gQ7kNvwFJbYMp&_nc_gid=1Uz9GzkoOm5RERNhmxMMFQ&edm=AOQ1c0wBAAAA&ccb=7-5&ig_cache_key=MzgyMjMxNjY3NTU5Nzk0ODcyMQ%3D%3D.3-ccb7-5&oh=00_AfxeiM7AiKYhYDFZ4DnIMDGveWsSSqJdOt0V7HTd20t-DQ&oe=69BDB53B&_nc_sid=8b3546, https://scontent-iad3-2.cdninstagram.com/v/t51.82787-15/624823170_18530129083068336_4566934327069630923_n.heic?stp=dst-jpg_e35_s1080x1080_sh0.08_tt6&_nc_ht=scontent-iad3-2.cdninstagram.com&_nc_cat=100&_nc_oc=Q6cZ2QF4_ne5iN-IAFuxkpnTotn60cdpP-DocHD14HxlgKMganw4uoJ0AgT7c8CPZ9tZnEg&_nc_ohc=KY5p58zE7rwQ7kNvwFeO9OW&_nc_gid=1Uz9GzkoOm5RERNhmxMMFQ&edm=AOQ1c0wBAAAA&ccb=7-5&ig_cache_key=MzgyMjMxNTA1MDI5Njc5MTE0NQ%3D%3D.3-ccb7-5&oh=00_AfztBXuO53uJD7hIFo-J-A-g6QB0IA7TyGZkUvL04TC54A&oe=69BDA7EA&_nc_sid=8b3546, https://scontent-iad3-2.cdninstagram.com/v/t51.82787-15/625204535_18530061052068336_2254622707446308490_n.heic?stp=dst-jpg_e35_s1080x1080_sh0.08_tt6&_nc_ht=scontent-iad3-2.cdninstagram.com&_nc_cat=100&_nc_oc=Q6cZ2QF4_ne5iN-IAFuxkpnTotn60cdpP-DocHD14HxlgKMganw4uoJ0AgT7c8CPZ9tZnEg&_nc_ohc=T4nxl1eOMlIQ7kNvwEb8-8a&_nc_gid=1Uz9GzkoOm5RERNhmxMMFQ&edm=AOQ1c0wBAAAA&ccb=7-5&ig_cache_key=MzgyMjE4NzU0NTg5NjI1ODgxNw%3D%3D.3-ccb7-5&oh=00_AfzLUVXX7O8oWXXl08rMvixUSBa7L0b5zpeGb0-AqPiU7Q&oe=69BDB6C3&_nc_sid=8b3546, https://scontent-iad3-2.cdninstagram.com/v/t51.82787-15/624944082_18529865083068336_5749358781468525952_n.heic?stp=dst-jpg_e35_s1080x1080_sh0.08_tt6&_nc_ht=scontent-iad3-2.cdninstagram.com&_nc_cat=100&_nc_oc=Q6cZ2QF4_ne5iN-IAFuxkpnTotn60cdpP-DocHD14HxlgKMganw4uoJ0AgT7c8CPZ9tZnEg&_nc_ohc=mi9DGRUKFsMQ7kNvwGgodAr&_nc_gid=1Uz9GzkoOm5RERNhmxMMFQ&edm=AOQ1c0wBAAAA&ccb=7-5&ig_cache_key=MzgyMTUzMjU4ODIzOTA3MDg5NA%3D%3D.3-ccb7-5&oh=00_AfzUDluSTpUiENgMfNy3qo99GCmhBC3jOC4RRU1TzvgxrQ&oe=69BD9C7F&_nc_sid=8b3546, https://scontent-iad3-2.cdninstagram.com/v/t51.82787-15/625204648_18529864651068336_2195409626985506752_n.heic?stp=dst-jpg_e35_s1080x1080_sh0.08_tt6&_nc_ht=scontent-iad3-2.cdninstagram.com&_nc_cat=100&_nc_oc=Q6cZ2QF4_ne5iN-IAFuxkpnTotn60cdpP-DocHD14HxlgKMganw4uoJ0AgT7c8CPZ9tZnEg&_nc_ohc=Nl3K9gxwm4UQ7kNvwEXrJiJ&_nc_gid=1Uz9GzkoOm5RERNhmxMMFQ&edm=AOQ1c0wBAAAA&ccb=7-5&ig_cache_key=MzgyMTUzMTUyNjgyMDA2OTcyMA%3D%3D.3-ccb7-5&oh=00_AfwMdD6Mikkt_FURzHTnlpYoqwqFDFBRTweVgIpsQLIwxg&oe=69BD9EA1&_nc_sid=8b3546, https://scontent-iad3-2.cdninstagram.com/v/t51.82787-15/625140264_18529624555068336_4333841618875518379_n.heic?stp=dst-jpg_e35_s1080x1080_sh0.08_tt6&_nc_ht=scontent-iad3-2.cdninstagram.com&_nc_cat=100&_nc_oc=Q6cZ2QF4_ne5iN-IAFuxkpnTotn60cdpP-DocHD14HxlgKMganw4uoJ0AgT7c8CPZ9tZnEg&_nc_ohc=kYAx7ebVmt4Q7kNvwEFPWoc&_nc_gid=1Uz9GzkoOm5RERNhmxMMFQ&edm=AOQ1c0wBAAAA&ccb=7-5&ig_cache_key=MzgyMDkxMzE3MjM0MjIzOTY0Mw%3D%3D.3-ccb7-5&oh=00_AfyAAPkIbx-0k4IhPqmnb0ztmZhq3N_y9oK83GxThAUyEg&oe=69BDB8B6&_nc_sid=8b3546 | Z2: https://scontent-iad3-1.cdninstagram.com/o1/v/t2/f2/m86/AQN9IAvzBlJ00KdxXojw7J9DffaLxigQTn-MUUVjBniN6qHyxjUqF_HXGE2Q1LgYhRQuMJUK1nOPlW-nZlbroUyR9LBP6qqqIq1jUqo.mp4?_nc_cat=110&_nc_sid=5e9851&_nc_ht=scontent-iad3-1.cdninstagram.com&_nc_ohc=D2jNu6hoL20Q7kNvwHnqaXa&efg=eyJ2ZW5jb2RlX3RhZyI6Inhwdl9wcm9ncmVzc2l2ZS5JTlNUQUdSQU0uQ0xJUFMuQzMuNzIwLmRhc2hfYmFzZWxpbmVfMV92MSIsInhwdl9hc3NldF9pZCI6MTc5MzU2NDEyNTgxNDk4NTYsImFzc2V0X2FnZV9kYXlzIjo0MiwidmlfdXNlY2FzZV9pZCI6MTAwOTksImR1cmF0aW9uX3MiOjUsInVybGdlbl9zb3VyY2UiOiJ3d3cifQ%3D%3D&ccb=17-1&vs=4fdf8fb7bcba5249&_nc_vs=HBksFQIYUmlnX3hwdl9yZWVsc19wZXJtYW5lbnRfc3JfcHJvZC9FQjRFQTM4M0NGNTM2RjVCOUI1MTFGRUZDRTI3MEY4OF92aWRlb19kYXNoaW5pdC5tcDQVAALIARIAFQIYUWlnX3hwdl9wbGFjZW1lbnRfcGVybWFuZW50X3YyLzY4NDU4QkYyODI1RDcxNzU2RTk4NEE2NDNDMkVFRDg3X2F1ZGlvX2Rhc2hpbml0Lm1wNBUCAsgBEgAoABgAGwKIB3VzZV9vaWwBMRJwcm9ncmVzc2l2ZV9yZWNpcGUBMRUAACbAn5bg3JfcPxUCKAJDMywXQBQhysCDEm8YEmRhc2hfYmFzZWxpbmVfMV92MREAdf4HZeadAQA&_nc_gid=1Uz9GzkoOm5RERNhmxMMFQ&_nc_ss=1a&_nc_zt=28&oh=00_AfwJ38cXm8NC6y-Zjxj_Y1wqDgI4Lfz_nxqCxTqch-LZMA&oe=69B9B297, https://scontent-iad3-2.cdninstagram.com/o1/v/t2/f2/m86/AQOzejS7p7R9jDh9lvYoTR48LB5k03lYcc72-Llkv2PmyvBd0Gt7w7PgcvS5jG_B3Pn0-htLFVODPx-oNL0IoxcSFR_231Y20aUrUko.mp4?_nc_cat=100&_nc_sid=5e9851&_nc_ht=scontent-iad3-2.cdninstagram.com&_nc_ohc=ckUV_u-4BjcQ7kNvwEYdQgz&efg=eyJ2ZW5jb2RlX3RhZyI6Inhwdl9wcm9ncmVzc2l2ZS5JTlNUQUdSQU0uQ0xJUFMuQzMuNzIwLmRhc2hfYmFzZWxpbmVfMV92MSIsInhwdl9hc3NldF9pZCI6MTc5MzU1MzgwNjQxNDk4NTYsImFzc2V0X2FnZV9kYXlzIjo0MywidmlfdXNlY2FzZV9pZCI6MTAwOTksImR1cmF0aW9uX3MiOjUsInVybGdlbl9zb3VyY2UiOiJ3d3cifQ%3D%3D&ccb=17-1&vs=32fad8171ddab06c&_nc_vs=HBksFQIYUmlnX3hwdl9yZWVsc19wZXJtYW5lbnRfc3JfcHJvZC9BMjQ2NzE3RUVDOTYzOTY3RTM0OTg0NDczQTQ2OUY5Q192aWRlb19kYXNoaW5pdC5tcDQVAALIARIAFQIYUWlnX3hwdl9wbGFjZW1lbnRfcGVybWFuZW50X3YyL0NENDdBMzIwRkY5MEFCRThFNDA2MkMzQUIxNkY4RDlFX2F1ZGlvX2Rhc2hpbml0Lm1wNBUCAsgBEgAoABgAGwKIB3VzZV9vaWwBMRJwcm9ncmVzc2l2ZV9yZWNpcGUBMRUAACbAtdry25HcPxUCKAJDMywXQBQhysCDEm8YEmRhc2hfYmFzZWxpbmVfMV92MREAdf4HZeadAQA&_nc_gid=1Uz9GzkoOm5RERNhmxMMFQ&_nc_ss=1a&_nc_zt=28&oh=00_AfwRMEIaB2WeGojlaZ_gdUfZntVde56mlGeE4xF-Y5jwuw&oe=69B9B579, https://scontent-iad3-2.cdninstagram.com/o1/v/t2/f2/m86/AQNv2Sy6sVGLCXFhyV7NpeiTnARHHqIxzBFE52DPbXEy-wHwhb4q8M9O99kM_9XxkyUU54ewWf8dmAv7CaA-q4iIV-ujqxupSjOtcnM.mp4?_nc_cat=105&_nc_sid=5e9851&_nc_ht=scontent-iad3-2.cdninstagram.com&_nc_ohc=JmC6xinXKNkQ7kNvwEaPFqh&efg=eyJ2ZW5jb2RlX3RhZyI6Inhwdl9wcm9ncmVzc2l2ZS5JTlNUQUdSQU0uQ0xJUFMuQzMuNzIwLmRhc2hfYmFzZWxpbmVfMV92MSIsInhwdl9hc3NldF9pZCI6MTc5MzU0MDI3MTkxNDk4NTYsImFzc2V0X2FnZV9kYXlzIjo0NCwidmlfdXNlY2FzZV9pZCI6MTAwOTksImR1cmF0aW9uX3MiOjUsInVybGdlbl9zb3VyY2UiOiJ3d3cifQ%3D%3D&ccb=17-1&vs=f97412d6216c3869&_nc_vs=HBksFQIYUmlnX3hwdl9yZWVsc19wZXJtYW5lbnRfc3JfcHJvZC8xMDQ3NzgyNTVGMUQ0RkJERDEyQTE4QkI4MTYzM0VCQV92aWRlb19kYXNoaW5pdC5tcDQVAALIARIAFQIYUWlnX3hwdl9wbGFjZW1lbnRfcGVybWFuZW50X3YyLzJDNEZDNzdEMjM2OEIzQ0VENkE2MERGRUJFN0YzNTg0X2F1ZGlvX2Rhc2hpbml0Lm1wNBUCAsgBEgAoABgAGwKIB3VzZV9vaWwBMRJwcm9ncmVzc2l2ZV9yZWNpcGUBMRUAACbA_NO_64ncPxUCKAJDMywXQBQhysCDEm8YEmRhc2hfYmFzZWxpbmVfMV92MREAdf4HZeadAQA&_nc_gid=1Uz9GzkoOm5RERNhmxMMFQ&_nc_ss=1a&_nc_zt=28&oh=00_Afxg7UGZYyO8kExaFs8kxx6SZzdWivy_bixUp0hoA241Fg&oe=69B9B902, https://scontent-iad3-1.cdninstagram.com/o1/v/t2/f2/m86/AQOGbnnAISke8z1AlZ27XyiDDix35QH1yuzlsqw4X2Km90Q9A8ziKaDefffwdLIUJtgcjv65Jp_vXd3pxn2p9_z0Q-_nd5Kl1GRJkrg.mp4?_nc_cat=109&_nc_sid=5e9851&_nc_ht=scontent-iad3-1.cdninstagram.com&_nc_ohc=UFYt_Rh4bkEQ7kNvwHCfN3h&efg=eyJ2ZW5jb2RlX3RhZyI6Inhwdl9wcm9ncmVzc2l2ZS5JTlNUQUdSQU0uQ0xJUFMuQzMuMTI4MC5kYXNoX2Jhc2VsaW5lXzFfdjEiLCJ4cHZfYXNzZXRfaWQiOjE3OTM1Mzk1NDA4MTQ5ODU2LCJhc3NldF9hZ2VfZGF5cyI6NDQsInZpX3VzZWNhc2VfaWQiOjEwMDk5LCJkdXJhdGlvbl9zIjo1LCJ1cmxnZW5fc291cmNlIjoid3d3In0%3D&ccb=17-1&vs=64479dbc4e999247&_nc_vs=HBksFQIYUmlnX3hwdl9yZWVsc19wZXJtYW5lbnRfc3JfcHJvZC85MDQzNDdBQTI1QTVEMUY0REZEM0VFMkY2RkY4ODE4OV92aWRlb19kYXNoaW5pdC5tcDQVAALIARIAFQIYUWlnX3hwdl9wbGFjZW1lbnRfcGVybWFuZW50X3YyLzhCNEE0N0Y1MkRGNzI2Qzc1QTE2QkEyNzA3NkYxQzkxX2F1ZGlvX2Rhc2hpbml0Lm1wNBUCAsgBEgAoABgAGwKIB3VzZV9vaWwBMRJwcm9ncmVzc2l2ZV9yZWNpcGUBMRUAACbA9auDtYncPxUCKAJDMywXQBQhysCDEm8YEmRhc2hfYmFzZWxpbmVfMV92MREAdf4HZeadAQA&_nc_gid=1Uz9GzkoOm5RERNhmxMMFQ&_nc_ss=1a&_nc_zt=28&oh=00_Afw3l40keS_5djY_VfHUOzEGmwfa0sjNb2SVrhZcnPjKrQ&oe=69B9C0CE, https://scontent-iad3-1.cdninstagram.com/o1/v/t2/f2/m86/AQOPK3vvcKJoOroBHEUhx9qxRxEhtIIjs04d1iysRAA3hNDqdrfWB0zZNMiU2TRhVez-uQ5m2eT8z0DWLbFhFYJhpOaJgy4laNiirlY.mp4?_nc_cat=110&_nc_sid=5e9851&_nc_ht=scontent-iad3-1.cdninstagram.com&_nc_ohc=EMY9XvmIW4kQ7kNvwFjxwb6&efg=eyJ2ZW5jb2RlX3RhZyI6Inhwdl9wcm9ncmVzc2l2ZS5JTlNUQUdSQU0uQ0xJUFMuQzMuNzIwLmRhc2hfYmFzZWxpbmVfMV92MSIsInhwdl9hc3NldF9pZCI6MTc5MzUzOTA3NDkxNDk4NTYsImFzc2V0X2FnZV9kYXlzIjo0NCwidmlfdXNlY2FzZV9pZCI6MTAwOTksImR1cmF0aW9uX3MiOjEwLCJ1cmxnZW5fc291cmNlIjoid3d3In0%3D&ccb=17-1&vs=91c4305ff100753f&_nc_vs=HBksFQIYUmlnX3hwdl9yZWVsc19wZXJtYW5lbnRfc3JfcHJvZC82NTQ4RUM0MjQ3MDdGQkE1Qjc5MjZDNUIxRkE1OENBQl92aWRlb19kYXNoaW5pdC5tcDQVAALIARIAFQIYUWlnX3hwdl9wbGFjZW1lbnRfcGVybWFuZW50X3YyLzhGNDk3RkY0ODM0MTg2MjY4Q0VDRkVENUYyNTU4QTk0 | AA2: 19 | AB2: 1 | AC2: 46097 | AD2: loupethis | AE2: collector_page | AF2: https://www.instagram.com/gunnertachejose
A3: abogado_casas | B3: instagram | C3: Alejandro Casas | D3: Personal Injury Attorney-Owner of Casas Law P.A.; Watches, Whiskey and, Cigars. | E3: 869 | F3: 2807 | G3: 175 | H3: FALSE | I3: FALSE | L3: https://instagram.fyto1-2.fna.fbcdn.net/v/t51.2885-19/431698407_929956895117509_3137349195214736088_n.jpg?stp=dst-jpg_e0_s150x150_tt6&efg=eyJ2ZW5jb2RlX3RhZyI6InByb2ZpbGVfcGljLmRqYW5nby4xMDgwLmMyIn0&_nc_ht=instagram.fyto1-2.fna.fbcdn.net&_nc_cat=101&_nc_oc=Q6cZ2QGN2q_9e63hviuPUfLgrrXn-vgVmnrF0H5SjWXWXU23NIQhl6ygTJWoFrxhgjJipCg&_nc_ohc=dpMRisC0vkQQ7kNvwFWJADr&_nc_gid=fhJwiM6umqPJBRfXbBA-Gw&edm=AOQ1c0wBAAAA&ccb=7-5&oh=00_Afwc2Sa9Qo1oPCXD1TkwnogtU7pMM8MHx9lmKmhNYRCOaA&oe=69BDA5E2&_nc_sid=8b3546 | O3: 0.0533 | P3: HAPPY BIRTHDAY, SUSIE! You are the love of my life, my wife, best friend and partner in all things. I wish for you a lifetime filled with love, happiness and adventure. Love you! | Thankful for good friends. Goodbye 2025! Palm Beach Watch Club. | Wishing all of our friends and family the very best of the season. Looking forward to a new year filled with health, happiness and prosperity. | Christmas Markets Stop #8. Dresden This beautiful city was completely destroyed in World War II. It has now been rebuilt with much of the original materials. You can look at the old buildings and easily recognize the original stones because they were left blackened as they looked after the bombings. | The Casas Law Family Christmas dinner. We are truly blessed to be in the company of such a fantastic group of people. There was too much food, too many drinks and an evening filled with laughs. Thank you to Ernesto from Paella Uno Catering for making the amazing dinner and to Megan Burr of Bite Hau | Stop #7 Frankfurt & Weisbaden. I mistakenly labeled the prior stop as Weisbaden but, this is it. Frankfurt is a big city with several Christmas markets and much to see. It’s a modern city that still retains some old world charm. The market in Weisbaden is known as the shooting star Christmas market. | Stop #6 Wertheim Another well preserved medieval town. This town sits between two rivers and has flooded many times over the centuries. There are numerous flood marks that are unsettlingly high on the walls. There is a beautiful old Lutheran Church that started out as a Catholic Church. There are | Stop #5. The Franconian village of Aschfeld. This tiny village was untouched by the Second World War. Well over 1,000 years old. It was too small to surround itself with a wall and most grew around a fortified church which was the center of activity. We saw many restored rooms depicting life over th | Stop #4 Wurzburg: We visited the Christmas Market and the Residenz which is a baroque 18th century palace built for the prince-bishops. | Stop #3. Rothenberg. This is an almost completely preserved medieval city. Walt Disney visited this town in the 1930’s and modeled Pinocchio’s village after it. We had warm apple strudel and hot chocolate in a hotel that was built in 1300. Another great day. | Stop #2. Bamberg A fairly small market but such a cool town. | Q3: #8, #7, #6, #5, #4, #3, #2 | S3: https://instagram.com/p/DUDYt2vjK2O, https://instagram.com/p/DS_VpuuFZNJ, https://instagram.com/p/DSyVsGeAXP2, https://instagram.com/p/DSr6STJFZZI, https://instagram.com/p/DSf2zv2gVbN, https://instagram.com/p/DSQZVs-gYex, https://instagram.com/p/DSFqdLnFdEJ, https://instagram.com/p/DSE_H_ukSOa, https://instagram.com/p/DR-lWuwlBJX, https://instagram.com/p/DR8CSgxgZaD, https://instagram.com/p/DR48lkKgHBn, https://instagram.com/p/DR2z6gtEewQ | T3: 51, 42, 70, 58, 60, 56, 39, 20, 28, 40, 35, 24 | U3: 15, 2, 7, 2, 0, 1, 1, 2, 0, 1, 2, 0 | V3: 2026-01-28, 2026-01-02, 2025-12-28, 2025-12-25, 2025-12-20, 2025-12-14, 2025-12-10, 2025-12-10, 2025-12-07, 2025-12-06, 2025-12-05, 2025-12-04 | W3: Antigua, Carribbean, Würzburg, Germany | X3: Image, Image, Sidecar, Image, Sidecar, Sidecar, Sidecar, Sidecar, Sidecar, Sidecar, Sidecar, Sidecar | Y3: https://instagram.fyto1-1.fna.fbcdn.net/v/t39.30808-6/624539548_4338479249813019_5618141011669941887_n.jpg?stp=dst-jpg_e35_p1080x1080_sh0.08_tt6&_nc_ht=instagram.fyto1-1.fna.fbcdn.net&_nc_cat=103&_nc_oc=Q6cZ2QGN2q_9e63hviuPUfLgrrXn-vgVmnrF0H5SjWXWXU23NIQhl6ygTJWoFrxhgjJipCg&_nc_ohc=Ot1X7YQyH0IQ7kNvwGFKKAk&_nc_gid=fhJwiM6umqPJBRfXbBA-Gw&edm=AOQ1c0wAAAAA&ccb=7-5&ig_cache_key=MzgyMDAwNTYxMzIxMjgzOTMxMA%3D%3D.3-ccb7-5&oh=00_AfyemXgMB5AEXIHg3fGSty1ey4rgBlt-CTIJkb-vl5HWoA&oe=69BD9226&_nc_sid=8b3546, https://instagram.fyto1-2.fna.fbcdn.net/v/t51.82787-15/609533529_18007216970821806_8806535578618323406_n.jpg?stp=dst-jpg_e35_p1080x1080_sh0.08_tt6&_nc_ht=instagram.fyto1-2.fna.fbcdn.net&_nc_cat=106&_nc_oc=Q6cZ2QGN2q_9e63hviuPUfLgrrXn-vgVmnrF0H5SjWXWXU23NIQhl6ygTJWoFrxhgjJipCg&_nc_ohc=VfhpOCYYx0EQ7kNvwFapH7H&_nc_gid=fhJwiM6umqPJBRfXbBA-Gw&edm=AOQ1c0wBAAAA&ccb=7-5&ig_cache_key=MzgwMDg1MTgzNzE2NDU1NzEyOQ%3D%3D.3-ccb7-5&oh=00_Afzyw8PRk12o2WdwbXb9WyFPuc3GABFCQm-KtfIyDq3Nww&oe=69BD9D64&_nc_sid=8b3546, https://instagram.fyto1-2.fna.fbcdn.net/v/t51.82787-15/602716518_18006621941821806_9034530550002112950_n.jpg?stp=dst-jpg_e35_s1080x1080_sh0.08_tt6&_nc_ht=instagram.fyto1-2.fna.fbcdn.net&_nc_cat=106&_nc_oc=Q6cZ2QGN2q_9e63hviuPUfLgrrXn-vgVmnrF0H5SjWXWXU23NIQhl6ygTJWoFrxhgjJipCg&_nc_ohc=et59naadZHAQ7kNvwHUj_Cb&_nc_gid=fhJwiM6umqPJBRfXbBA-Gw&edm=AOQ1c0wBAAAA&ccb=7-5&ig_cache_key=Mzc5NzE5MjgxMTg0MTk2NjQ5Mw%3D%3D.3-ccb7-5&oh=00_Afz5aiR_R3HMRCN8pnrwTrxUlmAonjzXR0HKfzUYU1Im7A&oe=69BDB46E&_nc_sid=8b3546, https://instagram.fyto1-2.fna.fbcdn.net/v/t51.82787-15/602716518_18006621941821806_9034530550002112950_n.jpg?stp=dst-jpg_e35_s1080x1080_sh0.08_tt6&_nc_ht=instagram.fyto1-2.fna.fbcdn.net&_nc_cat=106&_nc_oc=Q6cZ2QGN2q_9e63hviuPUfLgrrXn-vgVmnrF0H5SjWXWXU23NIQhl6ygTJWoFrxhgjJipCg&_nc_ohc=et59naadZHAQ7kNvwHUj_Cb&_nc_gid=fhJwiM6umqPJBRfXbBA-Gw&edm=AOQ1c0wBAAAA&ccb=7-5&ig_cache_key=Mzc5NzE5MjgxMTg0MTk2NjQ5Mw%3D%3D.3-ccb7-5&oh=00_Afz5aiR_R3HMRCN8pnrwTrxUlmAonjzXR0HKfzUYU1Im7A&oe=69BDB46E&_nc_sid=8b3546, https://instagram.fyto1-2.fna.fbcdn.net/v/t51.82787-15/590367460_18006621953821806_2721736594605781782_n.jpg?stp=dst-jpg_e35_s1080x1080_sh0.08_tt6&_nc_ht=instagram.fyto1-2.fna.fbcdn.net&_nc_cat=106&_nc_oc=Q6cZ2QGN2q_9e63hviuPUfLgrrXn-vgVmnrF0H5SjWXWXU23NIQhl6ygTJWoFrxhgjJipCg&_nc_ohc=PjNzPObTnvQQ7kNvwGa4mGM&_nc_gid=fhJwiM6umqPJBRfXbBA-Gw&edm=AOQ1c0wBAAAA&ccb=7-5&ig_cache_key=Mzc5NzE5MjgxMjE2OTA3MTkzMw%3D%3D.3-ccb7-5&oh=00_AfylAqMB2ICa14dfxxQJHs6dDCd2Ayq1GYP-vV4RtaxL1Q&oe=69BDB43E&_nc_sid=8b3546, https://instagram.fyto1-2.fna.fbcdn.net/v/t51.82787-15/603069925_18006621962821806_7938595125366558076_n.jpg?stp=dst-jpg_e35_s1080x1080_sh0.08_tt6&_nc_ht=instagram.fyto1-2.fna.fbcdn.net&_nc_cat=106&_nc_oc=Q6cZ2QGN2q_9e63hviuPUfLgrrXn-vgVmnrF0H5SjWXWXU23NIQhl6ygTJWoFrxhgjJipCg&_nc_ohc=kMLWGDV7oq4Q7kNvwFUBGwI&_nc_gid=fhJwiM6umqPJBRfXbBA-Gw&edm=AOQ1c0wBAAAA&ccb=7-5&ig_cache_key=Mzc5NzE5MjgxMTgyNTE4NDg5MA%3D%3D.3-ccb7-5&oh=00_AfyQm38w6Eh5rK70Mm0fHik0bsyw6Y20w8ZTJ3GM5sdvWA&oe=69BDB2A9&_nc_sid=8b3546, https://instagram.fyto1-2.fna.fbcdn.net/v/t51.82787-15/587791479_18006351173821806_4339232795343398157_n.jpg?stp=dst-jpg_e35_p1080x1080_sh0.08_tt6&_nc_ht=instagram.fyto1-2.fna.fbcdn.net&_nc_cat=106&_nc_oc=Q6cZ2QGN2q_9e63hviuPUfLgrrXn-vgVmnrF0H5SjWXWXU23NIQhl6ygTJWoFrxhgjJipCg&_nc_ohc=fxqOYOTu-qYQ7kNvwE8vcar&_nc_gid=fhJwiM6umqPJBRfXbBA-Gw&edm=AOQ1c0wBAAAA&ccb=7-5&ig_cache_key=Mzc5NTM4MzQ1NTE5MTUwNDQ1Ng%3D%3D.3-ccb7-5&oh=00_AfwAu4KyI5yPHBvWy061FN2V-zoZdZ54Pp1xpUevyEPGzQ&oe=69BDA5FC&_nc_sid=8b3546, https://instagram.fyto1-2.fna.fbcdn.net/v/t51.82787-15/589942231_18005836514821806_1060000011034679358_n.jpg?stp=dst-jpg_e35_p1080x1080_sh0.08_tt6&_nc_ht=instagram.fyto1-2.fna.fbcdn.net&_nc_cat=106&_nc_oc=Q6cZ2QGN2q_9e63hviuPUfLgrrXn-vgVmnrF0H5SjWXWXU23NIQhl6ygTJWoFrxhgjJipCg&_nc_ohc=jsoQeLdc3UQQ7kNvwEbfjnO&_nc_gid=fhJwiM6umqPJBRfXbBA-Gw&edm=AOQ1c0wBAAAA&ccb=7-5&ig_cache_key=Mzc5MTk5MDQzNDQwNjk3MzgyNg%3D%3D.3-ccb7-5&oh=00_AfzTtocM0MfcZq_tPcfAyHrNlHAbzXOBS9aS00Ag5QD1LA&oe=69BD935E&_nc_sid=8b3546, https://instagram.fyto1-2.fna.fbcdn.net/v/t51.82787-15/589942231_18005836514821806_1060000011034679358_n.jpg?stp=dst-jpg_e35_p1080x1080_sh0.08_tt6&_nc_ht=instagram.fyto1-2.fna.fbcdn.net&_nc_cat=106&_nc_oc=Q6cZ2QGN2q_9e63hviuPUfLgrrXn-vgVmnrF0H5SjWXWXU23NIQhl6ygTJWoFrxhgjJipCg&_nc_ohc=jsoQeLdc3UQQ7kNvwEbfjnO&_nc_gid=fhJwiM6umqPJBRfXbBA-Gw&edm=AOQ1c0wBAAAA&ccb=7-5&ig_cache_key=Mzc5MTk5MDQzNDQwNjk3MzgyNg%3D%3D.3-ccb7-5&oh=00_AfzTtocM0MfcZq_tPcfAyHrNlHAbzXOBS9aS00Ag5QD1LA&oe=69BD935E&_nc_sid=8b3546, https://instagram.fyto1-2.fna.fbcdn.net/v/t51.82787-15/603080092_18005836544821806_1601593861678180600_n.jpg?stp=dst-jpg_e35_p1080x1080_sh0.08_tt6&_nc_ht=instagram.fyto1-2.fna.fbcdn.net&_nc_cat=106&_nc_oc=Q6cZ2QGN2q_9e63hviuPUfLgrrXn-vgVmnrF0H5SjWXWXU23NIQhl6ygTJWoFrxhgjJipCg&_nc_ohc=UNeZA0DIfiEQ7kNvwExrLx7&_nc_gid=fhJwiM6umqPJBRfXbBA-Gw&edm=AOQ1c0wBAAAA&ccb=7-5&ig_cache_key=Mzc5MTk5MDQzNDQwNjk4Njg3OA%3D%3D.3-ccb7-5&oh=00_AfyYbSwa1zkL_wmzRVC8964rBtMDSX8TkSwP1TacbmbHLw&oe=69BDA89E&_nc_sid= | AA3: 44 | AB3: 3 | AC3: 46097 | AD3: loupethis | AE3: collector_page | AF3: https://www.instagram.com/abogado_casas
A4: noritera24 | B4: instagram | C4: 寺田 憲永 | E4: 263 | F4: 751 | G4: 69 | H4: FALSE | I4: FALSE | L4: https://scontent-sjc6-1.cdninstagram.com/v/t51.2885-19/476847396_651892737516527_1167557373126833247_n.jpg?stp=dst-jpg_e0_s150x150_tt6&efg=eyJ2ZW5jb2RlX3RhZyI6InByb2ZpbGVfcGljLmRqYW5nby41MDAuYzIifQ&_nc_ht=scontent-sjc6-1.cdninstagram.com&_nc_cat=111&_nc_oc=Q6cZ2QF1yPgdmWQ8bSJjpCokyM5dER8QBycS2wh5DAQ7_p1aKTR_oUAMmRTJ8LgSztCvKUA&_nc_ohc=ZCv-OkJe1tAQ7kNvwFHSAUO&_nc_gid=c0a-TjvY6fR91GXlq02zlg&edm=AOQ1c0wBAAAA&ccb=7-5&oh=00_AfzxUtpIQ8t0bawHCSt8wzIxSvU2s3Qnb3RjZD0mo7rLuQ&oe=69BD8E74&_nc_sid=8b3546 | O4: 0.0691 | P4: 近江八幡市ラコリーナの飛び出し坊やがかわいい。⁡ ⁡ #ラコリーナ #バームクーヘン | 天理市にある町中華の大和軒。ここのもやし炒めは最高に美味い。 #天理市 #町中華 #大和軒 #もやし炒め | 助けてください。帯状疱疹になってしまいました。剣山で刺されているような激痛です。 | 奈良県と京都府の境にあるその名も国境食堂。 腹が減ったらここのカツ丼をオススメ！ #国境食堂 #カツ丼 #大盛り | 先日の若草山の山焼き前の花火です。 #奈良市 #若草山 #山焼き | 今日は山焼きでした🔥 #若草山 #山焼き | いつまでも元気でいてね | ニンテンドーミュージアムだ‼️ | まさに別腹❗ | 我が生涯に一片の悔い無し❗ #北斗の拳大原画展 #ラオウ #巨星墜つ | はっ、これは！北斗天帰掌!! #北斗の拳大原画展 #トキ #兵庫県立美術館 | ひでぶっ！ #北斗の拳大原画展 #ハート様 #北斗柔破斬 | S4: https://instagram.com/p/DVKfvgxkpeJ, https://instagram.com/p/DLABHMWyqQA, https://instagram.com/p/DJiF92_TNtF, https://instagram.com/p/DI8fDNhSZQR, https://instagram.com/p/DFUHpr6yeAt, https://instagram.com/p/DFPs7NrSLRI, https://instagram.com/p/DE7S1M4SuAc, https://instagram.com/p/DE6oNM1y8qJ, https://instagram.com/p/DCEPOW7S8xC, https://instagram.com/p/C9sFnCry7aO, https://instagram.com/p/C9jyB7GS7XL, https://instagram.com/p/C9hZMY4ygR8 | T4: 9, 18, 6, 24, 27, 24, 16, 18, 20, 27, 17, 11 | U4: 0, 0, 1, 0, 0, 0, 0, 0, 0, 0, 0, 0 | V4: 2026-02-25, 2025-06-17, 2025-05-12, 2025-04-27, 2025-01-27, 2025-01-25, 2025-01-17, 2025-01-17, 2024-11-07, 2024-07-21, 2024-07-18, 2024-07-17 | X4: Video, Image, Image, Image, Video, Image, Image, Image, Image, Image, Image, Image | Y4: https://scontent-sjc3-1.cdninstagram.com/v/t51.82787-15/623390926_18039801947725596_8171532934446088184_n.jpg?stp=dst-jpg_e35_s1080x1080_sh0.08_tt6&_nc_ht=scontent-sjc3-1.cdninstagram.com&_nc_cat=100&_nc_oc=Q6cZ2QF1yPgdmWQ8bSJjpCokyM5dER8QBycS2wh5DAQ7_p1aKTR_oUAMmRTJ8LgSztCvKUA&_nc_ohc=KVrCwzLO5a8Q7kNvwE80TAP&_nc_gid=c0a-TjvY6fR91GXlq02zlg&edm=AOQ1c0wBAAAA&ccb=7-5&ig_cache_key=MzY1NjkyNzc4OTc3NDk3MTkwNA%3D%3D.3-ccb7-5&oh=00_Afyio9iE_OJY6zm9V5-UR8IKeuRdpEeaIA5avwMzebFaSA&oe=69BDB079&_nc_sid=8b3546, https://scontent-sjc6-1.cdninstagram.com/v/t51.82787-15/620897612_17887274766427585_5168461228460557261_n.jpg?stp=dst-jpg_e35_s1080x1080_sh0.08_tt6&_nc_ht=scontent-sjc6-1.cdninstagram.com&_nc_cat=101&_nc_oc=Q6cZ2QF1yPgdmWQ8bSJjpCokyM5dER8QBycS2wh5DAQ7_p1aKTR_oUAMmRTJ8LgSztCvKUA&_nc_ohc=wrQ-X7rzhjkQ7kNvwFxwiPf&_nc_gid=c0a-TjvY6fR91GXlq02zlg&edm=AOQ1c0wBAAAA&ccb=7-5&ig_cache_key=MzYzMDQ5MDQ5MDc3ODczNzQ3Nw%3D%3D.3-ccb7-5&oh=00_AfxmCkya5zucLN0w_ZfvY30Edo2Z5HO_oGR36nWLfieljQ&oe=69BD99DE&_nc_sid=8b3546, https://scontent-sjc6-1.cdninstagram.com/v/t51.82787-15/623515472_18063560801644149_3446559460627410548_n.jpg?stp=dst-jpg_e35_s1080x1080_sh0.08_tt6&_nc_ht=scontent-sjc6-1.cdninstagram.com&_nc_cat=109&_nc_oc=Q6cZ2QF1yPgdmWQ8bSJjpCokyM5dER8QBycS2wh5DAQ7_p1aKTR_oUAMmRTJ8LgSztCvKUA&_nc_ohc=dOF3UbSmsK0Q7kNvwG_vL7k&_nc_gid=c0a-TjvY6fR91GXlq02zlg&edm=AOQ1c0wBAAAA&ccb=7-5&ig_cache_key=MzYxOTkwNDc2MDYxNjQyNDQ2NQ%3D%3D.3-ccb7-5&oh=00_AfwzhPB2AdE8SSPhSsJhDBXryExNt6NSfO0c73PMfXOAmg&oe=69BDB2F4&_nc_sid=8b3546, https://scontent-sjc3-1.cdninstagram.com/v/t51.82787-15/622356808_17946552131962134_7831933523479587071_n.jpg?stp=dst-jpg_e35_s1080x1080_sh0.08_tt6&_nc_ht=scontent-sjc3-1.cdninstagram.com&_nc_cat=106&_nc_oc=Q6cZ2QF1yPgdmWQ8bSJjpCokyM5dER8QBycS2wh5DAQ7_p1aKTR_oUAMmRTJ8LgSztCvKUA&_nc_ohc=_bkZrFKmQ2EQ7kNvwHvDoiX&_nc_gid=c0a-TjvY6fR91GXlq02zlg&edm=AOQ1c0wBAAAA&ccb=7-5&ig_cache_key=MzU1MzI1NjIxNDE5OTA1NTQzMg%3D%3D.3-ccb7-5&oh=00_Afwz55L2e0Zyaky9kto5_XGgK51WoidZUlJpjtz9uryg3Q&oe=69BDB932&_nc_sid=8b3546, https://scontent-sjc3-1.cdninstagram.com/v/t51.82787-15/626538272_18050463545695625_7909197216043427244_n.jpg?stp=dst-jpg_e35_s1080x1080_sh0.08_tt6&_nc_ht=scontent-sjc3-1.cdninstagram.com&_nc_cat=105&_nc_oc=Q6cZ2QF1yPgdmWQ8bSJjpCokyM5dER8QBycS2wh5DAQ7_p1aKTR_oUAMmRTJ8LgSztCvKUA&_nc_ohc=2sOILFQDRXMQ7kNvwHIEh7c&_nc_gid=c0a-TjvY6fR91GXlq02zlg&edm=AOQ1c0wBAAAA&ccb=7-5&ig_cache_key=MzU0NzUxMTk1MjI4MzE5NzQ2OA%3D%3D.3-ccb7-5&oh=00_Afwcj9ORhihTfmdxYKO3DVW1Z9yC06vo8HgkHjTbwvbF5w&oe=69BD9134&_nc_sid=8b3546, https://scontent-sjc6-1.cdninstagram.com/v/t51.82787-15/629422017_18338209159240372_1702916677156418156_n.jpg?stp=dst-jpg_e35_s1080x1080_sh0.08_tt6&_nc_ht=scontent-sjc6-1.cdninstagram.com&_nc_cat=104&_nc_oc=Q6cZ2QF1yPgdmWQ8bSJjpCokyM5dER8QBycS2wh5DAQ7_p1aKTR_oUAMmRTJ8LgSztCvKUA&_nc_ohc=YTCBoGTmYo4Q7kNvwGHWTSl&_nc_gid=c0a-TjvY6fR91GXlq02zlg&edm=AOQ1c0wBAAAA&ccb=7-5&ig_cache_key=MzU0NzMyNDQ4NTUwODc3ODYzMw%3D%3D.3-ccb7-5&oh=00_Afzw0RASfraeCW1k6ktLmsnmDdw5ihaDgUJIWT1Wy6onTA&oe=69BD8C80&_nc_sid=8b3546, https://scontent-sjc6-1.cdninstagram.com/v/t51.82787-15/630630791_18403701019131093_4145509035250462642_n.jpg?stp=dst-jpg_e35_s1080x1080_sh0.08_tt6&_nc_ht=scontent-sjc6-1.cdninstagram.com&_nc_cat=109&_nc_oc=Q6cZ2QF1yPgdmWQ8bSJjpCokyM5dER8QBycS2wh5DAQ7_p1aKTR_oUAMmRTJ8LgSztCvKUA&_nc_ohc=H3QyYgCPzCQQ7kNvwGif1GP&_nc_gid=c0a-TjvY6fR91GXlq02zlg&edm=AOQ1c0wBAAAA&ccb=7-5&ig_cache_key=MzQ5NTk4NjE2ODEzMzgzMTc0Ng%3D%3D.3-ccb7-5&oh=00_AfzyWwyBNHw_npQ4fxb3QsAGemIeeTuVn_2Tx1bm9SFr4g&oe=69BDA2CF&_nc_sid=8b3546, https://scontent-sjc6-1.cdninstagram.com/v/t51.82787-15/624605385_18098245945927279_5895230937017004006_n.jpg?stp=dst-jpg_e35_s1080x1080_sh0.08_tt6&_nc_ht=scontent-sjc6-1.cdninstagram.com&_nc_cat=107&_nc_oc=Q6cZ2QF1yPgdmWQ8bSJjpCokyM5dER8QBycS2wh5DAQ7_p1aKTR_oUAMmRTJ8LgSztCvKUA&_nc_ohc=nKW_xPTxoyMQ7kNvwFR3Nfs&_nc_gid=c0a-TjvY6fR91GXlq02zlg&edm=AOQ1c0wBAAAA&ccb=7-5&ig_cache_key=MzQxNzEzMDg5MDQ0MTc2NjU0Mg%3D%3D.3-ccb7-5&oh=00_AfzLGL_4fYnAdoD828YPF1JU9i4XwIIsvUHWCOujAwW9EQ&oe=69BD91B8&_nc_sid=8b3546, https://scontent-sjc3-1.cdninstagram.com/v/t51.82787-15/623026720_18109574080709124_5283023880477568432_n.jpg?stp=dst-jpg_e35_s1080x1080_sh0.08_tt6&_nc_ht=scontent-sjc3-1.cdninstagram.com&_nc_cat=100&_nc_oc=Q6cZ2QF1yPgdmWQ8bSJjpCokyM5dER8QBycS2wh5DAQ7_p1aKTR_oUAMmRTJ8LgSztCvKUA&_nc_ohc=HwslnLQgx0IQ7kNvwFJ7fC2&_nc_gid=c0a-TjvY6fR91GXlq02zlg&edm=AOQ1c0wBAAAA&ccb=7-5&ig_cache_key=MzQxNDc5Mjk3Njk3ODM5MjUyMw%3D%3D.3-ccb7-5&oh=00_Afx6U6qFPwigv8fq7RDK-vipNKxgcMWw9C2sy329o5Gs3w&oe=69BD94B1&_nc_sid=8b3546, https://scontent-sjc3-1.cdninstagram.com/v/t51.82787-15/625045792_18149175013391990_6591410123138496031_n.jpg?stp=dst-jpg_e35_s1080x1080_sh0.08_tt6&_nc_ht=scontent-sjc3-1.cdninstagram.com&_nc_cat=102&_nc_oc=Q6cZ2QF1yPgdmWQ8bSJjpCokyM5dER8QBycS2wh5DAQ7_p1aKTR_oUAMmRTJ8LgSztCvKUA&_nc_ohc=O5-aTX8pWFwQ7kNvwGv10dU&_nc_gid=c0a-TjvY6fR91GXlq02zlg&edm=AOQ1c0wBAAAA&ccb=7-5&ig_cache_key=MzQxNDEyMDc5NTA0MjYxMjM0OA%3D%3D.3-ccb7-5&oh=00_AfzUgj6-cbfGIc2Fje1_TiwPhRShheBLPVO1derp1g0XA | Z4: https://scontent-sjc3-1.cdninstagram.com/o1/v/t16/f2/m69/AQMNeZRpyq8TWkgfRyXuzDXuk6uLI1IFs6X9NEBFEiZVVJVksAuss2J2tJCKScBRjXFoXGbBYv-sM8uWkUcfHInm.mp4?strext=1&_nc_cat=106&_nc_sid=5e9851&_nc_ht=scontent-sjc3-1.cdninstagram.com&_nc_ohc=jN0-HRIXfHUQ7kNvwF62BxK&efg=eyJ2ZW5jb2RlX3RhZyI6Inhwdl9wcm9ncmVzc2l2ZS5JTlNUQUdSQU0uQ0xJUFMuQzMuNzIwLmRhc2hfYmFzZWxpbmVfMV92MSIsInhwdl9hc3NldF9pZCI6MTc5NDkxODkwOTYwOTg5MjgsImFzc2V0X2FnZV9kYXlzIjoxOSwidmlfdXNlY2FzZV9pZCI6MTAwOTksImR1cmF0aW9uX3MiOjUsInVybGdlbl9zb3VyY2UiOiJ3d3cifQ%3D%3D&ccb=17-1&vs=1ea71a9632a3c&_nc_vs=HBkcFQIYOnBhc3N0aHJvdWdoX2V2ZXJzdG9yZS9HRnJzQVNZV19nMFY4M0VDQUxYb3YxeG16eEIxYnNwVEFRQUYVAALIARIAKAAYABsCiAd1c2Vfb2lsATEScHJvZ3Jlc3NpdmVfcmVjaXBlATEVAAAm4LGigais4j8VAigCQzMsF0AUIcrAgxJvGBJkYXNoX2Jhc2VsaW5lXzFfdjERAHX-B2XmnQEA&_nc_gid=c0a-TjvY6fR91GXlq02zlg&_nc_ss=1a&_nc_zt=28&oh=00_Afypp3HHgWwn140esTMLZAAc7ASxErPjYz7EbGrvrBO5CQ&oe=69BDB652, https://scontent-sjc6-1.cdninstagram.com/o1/v/t2/f2/m86/AQOcLDlilfmUY3mo0q6KYA4Z6x5M0d9i2-zljXS8W9Qix8Ddn1X4j63IdMGPeDm7BiK6rSOO9TXVeD4ahkG9tR9KshadO1x3flJfwTY.mp4?_nc_cat=104&_nc_sid=5e9851&_nc_ht=scontent-sjc6-1.cdninstagram.com&_nc_ohc=dSuDp0F62ZwQ7kNvwHQL5s4&efg=eyJ2ZW5jb2RlX3RhZyI6Inhwdl9wcm9ncmVzc2l2ZS5JTlNUQUdSQU0uQ0xJUFMuQzMuMzYwLmRhc2hfYmFzZWxpbmVfM192MSIsInhwdl9hc3NldF9pZCI6OTk2MTQ0OTk4OTkzNTM5LCJhc3NldF9hZ2VfZGF5cyI6NDEzLCJ2aV91c2VjYXNlX2lkIjoxMDA5OSwiZHVyYXRpb25fcyI6OTAsInVybGdlbl9zb3VyY2UiOiJ3d3cifQ%3D%3D&ccb=17-1&_nc_gid=c0a-TjvY6fR91GXlq02zlg&_nc_ss=1a&_nc_zt=28&vs=8f48ae413ff180c&_nc_vs=HBksFQIYUmlnX3hwdl9yZWVsc19wZXJtYW5lbnRfc3JfcHJvZC81MTQ2NTM5QTQ2NzMwRUZGNDMxREYxN0I2OUQ0MUVCMl92aWRlb19kYXNoaW5pdC5tcDQVAALIARIAFQIYRmlnX3hwdl9yZWVsc19wZXJtYW5lbnRfc3JfcHJvZC80OTE1NTQ3NzY5NzUzNDFfNDIyODEyMzU5MDY0MDE3Njc2NS5tcDQVAgLIARIAKAAYABsCiAd1c2Vfb2lsATEScHJvZ3Jlc3NpdmVfcmVjaXBlATEVAAAmhrr6zKL_xAMVAigCQzMsF0BWfU_fO2RaGBJkYXNoX2Jhc2VsaW5lXzNfdjERAHX-B2XmnQEA&oh=00_AfykdFx3VleI8ExLuV_L6mKZ3ccfuDfXMU5RmPXFcik-0w&oe=69B99C59 | AA4: 18 | AB4: 0 | AC4: 46097 | AD4: loupethis | AE4: collector_page | AF4: https://www.instagram.com/noritera24
A5: randallastout | B5: instagram | C5: Randall Stout | E5: 256 | F5: 1903 | G5: 10 | H5: FALSE | I5: FALSE | L5: https://instagram.feat1-1.fna.fbcdn.net/v/t51.2885-19/10995034_751782391607059_1655199174_a.jpg?stp=dst-jpg_e0_s150x150_tt6&efg=eyJ2ZW5jb2RlX3RhZyI6InByb2ZpbGVfcGljLmRqYW5nby4xNTAuYzIifQ&_nc_ht=instagram.feat1-1.fna.fbcdn.net&_nc_cat=107&_nc_oc=Q6cZ2QGOArsAUJST2fM8PXQZS_cKOhakikPL70tu157qONS9ci3Ywo4aoCC_dinQXKn7W1g&_nc_ohc=KSNNFb3rt88Q7kNvwGZwbrg&_nc_gid=Rn5gkxz-WSqp_QmAiqyh9w&edm=AOQ1c0wBAAAA&ccb=7-5&oh=00_AfwZVUBFo7bi0fu0Ih-amqmGLIsj_zocCKqo9LALk7w3pA&oe=69BDA83A&_nc_sid=8b3546 | O5: 0.0949 | P5: Maui always hits the sweet spot! #maui | Apua Point sunrise. #hawaii #sunrise #aloha | Aloha from Hawaii! #hawaii #aloha #rainbow #shaka | Bellows Beach #hawaii #hawaiilife #oahu #beach #ohana #beachlife #sunrise | Monk seals on Kaeana Point at the end of the hike. #kaeanapoint #hawaii #hawaiilife #hiking #oahu | Haleakala Crater epic 3 day hike. #nationalpark #hawaii #maui #backpacking #hiking #haleakala | Pedernales State Park is one of the jewels of Texas. #texashillcountry #texas #texasstaeparks #gooutside | Big Bend National Park. True Texas rugged beauty. #texas #texasoutdoors #nationalpark #bigbend #hiking | Texas/Mexico border at Big Bend National Park. Mexico left USA right. #texas #texasoutdoors #bigbend #riogrande #hiking #nationalpark | Texas Hill Country morning. #texas #hillcountry #rainbow #texashillcountry #morning | Q5: #maui, #hawaii, #sunrise, #aloha, #rainbow, #shaka, #hawaiilife, #oahu, #beach, #ohana, #beachlife, #kaeanapoint, #hiking, #nationalpark, #backpacking, #haleakala, #texashillcountry, #texas, #texasstaeparks, #gooutside, #texasoutdoors, #bigbend, #riogrande, #hillcountry, #morning | S5: https://instagram.com/p/Cq6vGfOsxi5, https://instagram.com/p/B6aU_JwnfXe, https://instagram.com/p/B6aUaCCHNYQ, https://instagram.com/p/Brw3vPHhXC3, https://instagram.com/p/Brw1kmzBQxk, https://instagram.com/p/BrwyueDhCcl, https://instagram.com/p/BqToCKXBEq0, https://instagram.com/p/BqKeYCYBCJQ, https://instagram.com/p/BqKdUQtBbpn, https://instagram.com/p/BqKcbwGhJDR | T5: 21, 20, 14, 36, 26, 33, 25, 32, 21, 10 | U5: 2, 0, 0, 0, 0, 0, 0, 2, 1, 0 | V5: 2023-04-12, 2019-12-23, 2019-12-23, 2018-12-24, 2018-12-24, 2018-12-24, 2018-11-18, 2018-11-14, 2018-11-14, 2018-11-14 | W5: Pedernales Falls State Park | X5: Sidecar, Image, Image, Sidecar, Sidecar, Sidecar, Sidecar, Sidecar, Image, Image | Y5: https://instagram.feat1-1.fna.fbcdn.net/v/t51.29350-15/340657872_1678421362629028_8174987527702465875_n.jpg?stp=dst-jpg_e35_s1080x1080_tt6&_nc_ht=instagram.feat1-1.fna.fbcdn.net&_nc_cat=104&_nc_oc=Q6cZ2QGOArsAUJST2fM8PXQZS_cKOhakikPL70tu157qONS9ci3Ywo4aoCC_dinQXKn7W1g&_nc_ohc=DUW2KkRDmz0Q7kNvwE-dfqi&_nc_gid=Rn5gkxz-WSqp_QmAiqyh9w&edm=AOQ1c0wBAAAA&ccb=7-5&ig_cache_key=MzA3ODk4MDQ0MDM2MjcwNzA4MA%3D%3D.3-ccb7-5&oh=00_AfzfzE2OQ2NbaPtoxI4Y59hNLdh24m_kDGY3WWDlBGDxjA&oe=69BD9510&_nc_sid=8b3546, https://instagram.feat1-1.fna.fbcdn.net/v/t51.29350-15/340657872_1678421362629028_8174987527702465875_n.jpg?stp=dst-jpg_e35_s1080x1080_tt6&_nc_ht=instagram.feat1-1.fna.fbcdn.net&_nc_cat=104&_nc_oc=Q6cZ2QGOArsAUJST2fM8PXQZS_cKOhakikPL70tu157qONS9ci3Ywo4aoCC_dinQXKn7W1g&_nc_ohc=DUW2KkRDmz0Q7kNvwE-dfqi&_nc_gid=Rn5gkxz-WSqp_QmAiqyh9w&edm=AOQ1c0wBAAAA&ccb=7-5&ig_cache_key=MzA3ODk4MDQ0MDM2MjcwNzA4MA%3D%3D.3-ccb7-5&oh=00_AfzfzE2OQ2NbaPtoxI4Y59hNLdh24m_kDGY3WWDlBGDxjA&oe=69BD9510&_nc_sid=8b3546, https://instagram.feat1-1.fna.fbcdn.net/v/t51.29350-15/340803674_691512369330787_3606777905602921519_n.jpg?stp=dst-jpg_e35_s1080x1080_tt6&_nc_ht=instagram.feat1-1.fna.fbcdn.net&_nc_cat=107&_nc_oc=Q6cZ2QGOArsAUJST2fM8PXQZS_cKOhakikPL70tu157qONS9ci3Ywo4aoCC_dinQXKn7W1g&_nc_ohc=78NEwZprkyQQ7kNvwFM_85y&_nc_gid=Rn5gkxz-WSqp_QmAiqyh9w&edm=AOQ1c0wBAAAA&ccb=7-5&ig_cache_key=MzA3ODk4MDQ0MDM3OTQ4MjE2Nw%3D%3D.3-ccb7-5&oh=00_AfxRM8NwOKoqIcNzenniXXYRmkKwGOX7StNv-1wWDdKHEQ&oe=69BDB95E&_nc_sid=8b3546, https://instagram.feat1-1.fna.fbcdn.net/v/t51.29350-15/340503206_3573203953002802_2114604039500305592_n.jpg?stp=dst-jpg_e35_s1080x1080_tt6&_nc_ht=instagram.feat1-1.fna.fbcdn.net&_nc_cat=110&_nc_oc=Q6cZ2QGOArsAUJST2fM8PXQZS_cKOhakikPL70tu157qONS9ci3Ywo4aoCC_dinQXKn7W1g&_nc_ohc=hY1r51imATEQ7kNvwGN7rJh&_nc_gid=Rn5gkxz-WSqp_QmAiqyh9w&edm=AOQ1c0wBAAAA&ccb=7-5&ig_cache_key=MzA3ODk4MDQ0MDM3OTU3NjE4NQ%3D%3D.3-ccb7-5&oh=00_AfzjTRdlq5PrOHd39culsx0Wwsjqowqyg0EzJgZuobGk3A&oe=69BDB9FC&_nc_sid=8b3546, https://instagram.feat1-1.fna.fbcdn.net/v/t51.29350-15/340816586_987792469296223_1944111262783992469_n.jpg?stp=dst-jpg_e35_s1080x1080_tt6&_nc_ht=instagram.feat1-1.fna.fbcdn.net&_nc_cat=107&_nc_oc=Q6cZ2QGOArsAUJST2fM8PXQZS_cKOhakikPL70tu157qONS9ci3Ywo4aoCC_dinQXKn7W1g&_nc_ohc=lLSBqth8XWoQ7kNvwEwRu2E&_nc_gid=Rn5gkxz-WSqp_QmAiqyh9w&edm=AOQ1c0wBAAAA&ccb=7-5&ig_cache_key=MzA3ODk4MDQ0MDM3OTQ5MTc4OA%3D%3D.3-ccb7-5&oh=00_AfyEYizKr79FNYaxhgEd_3d8PdKCbWwuisdU2P0gySKmRQ&oe=69BD9CA3&_nc_sid=8b3546, https://instagram.feat1-1.fna.fbcdn.net/v/t51.29350-15/340862953_146355141489759_8858516828834939274_n.jpg?stp=dst-jpg_e35_s1080x1080_tt6&_nc_ht=instagram.feat1-1.fna.fbcdn.net&_nc_cat=103&_nc_oc=Q6cZ2QGOArsAUJST2fM8PXQZS_cKOhakikPL70tu157qONS9ci3Ywo4aoCC_dinQXKn7W1g&_nc_ohc=-Z_6OA9w5J0Q7kNvwGdkHQO&_nc_gid=Rn5gkxz-WSqp_QmAiqyh9w&edm=AOQ1c0wBAAAA&ccb=7-5&ig_cache_key=MzA3ODk4MDQ0MDM3OTQ5NTY2NA%3D%3D.3-ccb7-5&oh=00_AfwQISOAs2pRMfguq70NbhqBe4HdLLidsoaXuRT39_x7Rw&oe=69BDAE76&_nc_sid=8b3546, https://instagram.feat1-1.fna.fbcdn.net/v/t51.29350-15/340843213_1280612262549588_3785486164969800256_n.jpg?stp=dst-jpg_e35_s1080x1080_tt6&_nc_ht=instagram.feat1-1.fna.fbcdn.net&_nc_cat=100&_nc_oc=Q6cZ2QGOArsAUJST2fM8PXQZS_cKOhakikPL70tu157qONS9ci3Ywo4aoCC_dinQXKn7W1g&_nc_ohc=B6fHTygPbdkQ7kNvwFqrKwF&_nc_gid=Rn5gkxz-WSqp_QmAiqyh9w&edm=AOQ1c0wBAAAA&ccb=7-5&ig_cache_key=MzA3ODk4MDQ0MDM3OTUxNzE5OQ%3D%3D.3-ccb7-5&oh=00_AfzWzJC--CfxKNe7AzhJwddZBj7C2eZ9MoMtbarX-uNyTg&oe=69BDAC59&_nc_sid=8b3546, https://instagram.feat1-1.fna.fbcdn.net/v/t51.29350-15/340476283_1155607365106777_7069126340872624172_n.jpg?stp=dst-jpg_e35_s1080x1080_tt6&_nc_ht=instagram.feat1-1.fna.fbcdn.net&_nc_cat=101&_nc_oc=Q6cZ2QGOArsAUJST2fM8PXQZS_cKOhakikPL70tu157qONS9ci3Ywo4aoCC_dinQXKn7W1g&_nc_ohc=0dVq5JA12cEQ7kNvwH3_Yy4&_nc_gid=Rn5gkxz-WSqp_QmAiqyh9w&edm=AOQ1c0wBAAAA&ccb=7-5&ig_cache_key=MzA3ODk4MDQ0MDM3OTU1MjYxOA%3D%3D.3-ccb7-5&oh=00_AfwfMO-BpyMMkVCKmSL1J2-VadVhlUIOOhG6WXnMTODDIw&oe=69BDB561&_nc_sid=8b3546, https://instagram.feat1-1.fna.fbcdn.net/v/t51.82787-15/649826470_18078968930377800_6276643227960842282_n.jpg?stp=dst-jpg_e35_s1080x1080_sh0.08_tt6&_nc_ht=instagram.feat1-1.fna.fbcdn.net&_nc_cat=100&_nc_oc=Q6cZ2QGOArsAUJST2fM8PXQZS_cKOhakikPL70tu157qONS9ci3Ywo4aoCC_dinQXKn7W1g&_nc_ohc=v6YLAGhJ9kkQ7kNvwHN8-W-&_nc_gid=Rn5gkxz-WSqp_QmAiqyh9w&edm=AOQ1c0wBAAAA&ccb=7-5&ig_cache_key=MzA3ODk4MDQ0MDM3MTEyNDQzNw%3D%3D.3-ccb7-5&oh=00_AfwdJGbj4Rz_dXROC1dLTLbO6awGb2wdt8TQAb6MrdI8Gg&oe=69BD907F&_nc_sid=8b3546, https://instagram.feat1-1.fna.fbcdn.net/v/t51.82787-15/651459367_18013884842669995_3238469732425330579_n.jpg?stp=dst-jpg_e35_s1080x1080_sh0.08_tt6&_nc_ht=instagram.feat1-1.fna.fbcdn.net&_nc_cat=107&_nc_oc=Q6cZ2QGOArsAUJST2fM8PXQZS_cKOhakikPL70tu157qONS9ci3Ywo4aoCC_dinQXKn7W1g&_nc_ohc=JPuuzPRyLTIQ7kNvwEKrFHv&_nc_gid=Rn5gkxz-WSqp_QmAiqyh9w&edm=AOQ1c0wBAAAA&ccb=7-5&ig_cache_key=MzA3ODk4MDQ0MDU0NzI1MTA2MA%3D%3D.3-ccb7-5&oh=00_AfwO4eXrLcPNPPFE9M68qlFn7ixAF89q1sJT50f1hlBAIQ&oe=69BDA901&_nc_sid=8b3546, https://instagram.feat1-1.fna.fbcdn.net/v/t51.29350-15/34 | Z5: https://instagram.feat1-1.fna.fbcdn.net/o1/v/t16/f2/m84/AQNjHVM0OvtuIgtzD3hkGUkKZ_i1VnLdL53wOAdgYAVwjL96fSjEbojfBkW1uMoriBcd6lQtZwu60t1wvr8iWJOuiSTXG-A1nL5hNJU.mp4?_nc_cat=111&_nc_oc=AdlAdZQlMrN6XTjsPO86kB4OpbM2J3TbYJ7nNT4tMw0-cIYLvjFIpI7fwqQkJopv3rU&_nc_sid=5e9851&_nc_ht=instagram.feat1-1.fna.fbcdn.net&_nc_ohc=owOmB7zJ33MQ7kNvwHzUlsl&efg=eyJ2ZW5jb2RlX3RhZyI6Inhwdl9wcm9ncmVzc2l2ZS5JTlNUQUdSQU0uQ0FST1VTRUxfSVRFTS5DMy42NDAuZGFzaF9iYXNlbGluZV8xX3YxIiwieHB2X2Fzc2V0X2lkIjoyOTU5NjgxODMyNDYzMjQsImFzc2V0X2FnZV9kYXlzIjoyNjUxLCJ2aV91c2VjYXNlX2lkIjoxMDE0NiwiZHVyYXRpb25fcyI6MjgsInVybGdlbl9zb3VyY2UiOiJ3d3cifQ%3D%3D&ccb=17-1&vs=3a48baf433d5b46f&_nc_vs=HBkcFQIYTGlnX2JhY2tmaWxsX3RpbWVsaW5lX3ZvZC8wMjQwRDFBNjI0MTUwOTE5OUQxMzJFRjBGM0RBNDFBRV92aWRlb19kYXNoaW5pdC5tcDQVAALIARIAKAAYABsCiAd1c2Vfb2lsATEScHJvZ3Jlc3NpdmVfcmVjaXBlATEVAAAm6Pfq5s7LhgEVAigCQzMsF0A8ogxJul41GBJkYXNoX2Jhc2VsaW5lXzFfdjERAHXuB2XEngEA&_nc_gid=Rn5gkxz-WSqp_QmAiqyh9w&_nc_ss=1a&_nc_zt=28&oh=00_AfxF9qWkaA1s39EbglTarE20-FuWpq0otSz9rBVe_3g0rA&oe=69B9BB6D | AA5: 24 | AB5: 1 | AC5: 46097 | AD5: loupethis | AE5: collector_page | AF5: https://www.instagram.com/randallastout
A6: gustavo_lopes_imagens | B6: instagram | C6: Gustavo Lopes | D6: Fotografia profissional. Whatsapp 16 99223 5263 | E6: 783 | F6: 1179 | G6: 220 | H6: FALSE | I6: FALSE | J6: Artist | K6: https://gustavolopesimagens.myportfolio.com/ | L6: https://scontent-phl2-1.cdninstagram.com/v/t51.2885-19/122009770_972297033262195_847262146995685250_n.jpg?stp=dst-jpg_e0_s150x150_tt6&efg=eyJ2ZW5jb2RlX3RhZyI6InByb2ZpbGVfcGljLmRqYW5nby4xMDgwLmMyIn0&_nc_ht=scontent-phl2-1.cdninstagram.com&_nc_cat=107&_nc_oc=Q6cZ2QFPWgNUb1KpcUUyXr4ds-2fIkhkHYd08XdLrBtvUKiX5WEtS6FVKMdUJCwbFCV3xCEfHlpcQYB_FSv18iWqwT6Y&_nc_ohc=iwsaVP3FaD0Q7kNvwFo49DP&_nc_gid=1pFHKT8-V7u_uRgJew64Sw&edm=AOQ1c0wBAAAA&ccb=7-5&oh=00_Afxlf1Y9oHxCyW4PEMea1rr6t9zowukcxCBnmwtYPEWo5g&oe=69BD95D6&_nc_sid=8b3546 | N6: 16 99223 5263 | O6: 0.0105 | P6: Trabalho realizado para @crizzapibolsasoficial ! | ... passagem de Som/Luz ! @sescfranca apresenta, @mawaca_oficial ! 06/12/2025 | ... passagem de Som/Luz ! @sescfranca apresenta, @mawaca_oficial ! | Para @cyateliebio ! | R6: @crizzapibolsasoficial, @sescfranca, @mawaca_oficial, @cyateliebio | S6: https://instagram.com/p/DV1zgRXia3y, https://instagram.com/p/DV1sImciWJw, https://instagram.com/p/DV1q5gVCS-d, https://instagram.com/p/DV1pjwmCR7q, https://instagram.com/p/DV1osJAiTPW, https://instagram.com/p/DV1oNiQCZFb, https://instagram.com/p/DUBk9yxibqb, https://instagram.com/p/DSoFFFZDF2V, https://instagram.com/p/DSP4yGIkQY5, https://instagram.com/p/DSAWoOCjQaF, https://instagram.com/p/DR-8RfRjI59, https://instagram.com/p/DRTpjPGjSAB | T6: 6, 3, 8, 3, 4, 3, 15, 1, 14, 22, 13, 5 | U6: 0, 0, 0, 0, 0, 0, 1, 0, 0, 1, 0, 0 | V6: 2026-03-13, 2026-03-13, 2026-03-13, 2026-03-13, 2026-03-13, 2026-03-13, 2026-01-27, 2025-12-24, 2025-12-14, 2025-12-08, 2025-12-08, 2025-11-21 | W6: Franca-SP, Taipu de Fora - Península de Maraú, Parque Nacional da Serra da Canastra, Sesc Franca, Franca SP | X6: Image, Video, Video, Video, Video, Video, Image, Image, Image, Image, Image, Image | Y6: https://scontent-phl2-1.cdninstagram.com/v/t51.82787-15/651921918_18075128885417012_1362013392195175345_n.webp?stp=dst-jpg_e35_s1080x1080_sh0.08_tt6&_nc_ht=scontent-phl2-1.cdninstagram.com&_nc_cat=108&_nc_oc=Q6cZ2QFPWgNUb1KpcUUyXr4ds-2fIkhkHYd08XdLrBtvUKiX5WEtS6FVKMdUJCwbFCV3xCEfHlpcQYB_FSv18iWqwT6Y&_nc_ohc=fFo-MREnCRIQ7kNvwE1Sp2e&_nc_gid=1pFHKT8-V7u_uRgJew64Sw&edm=AOQ1c0wBAAAA&ccb=7-5&ig_cache_key=Mzg1MjIxMTU3NDMyOTE1OTE1NA%3D%3D.3-ccb7-5&oh=00_AfxJNzBY90IRHxcWdnur5V-2ATFko7xCWtgvbXYnmFQOjQ&oe=69BDAEE8&_nc_sid=8b3546, https://scontent-phl2-1.cdninstagram.com/v/t51.82787-15/623834036_18070714028417012_1840575428941451126_n.webp?stp=dst-jpg_e35_s1080x1080_sh0.08_tt6&_nc_ht=scontent-phl2-1.cdninstagram.com&_nc_cat=108&_nc_oc=Q6cZ2QFPWgNUb1KpcUUyXr4ds-2fIkhkHYd08XdLrBtvUKiX5WEtS6FVKMdUJCwbFCV3xCEfHlpcQYB_FSv18iWqwT6Y&_nc_ohc=3kki3aiJZc0Q7kNvwEmRu9b&_nc_gid=1pFHKT8-V7u_uRgJew64Sw&edm=AOQ1c0wBAAAA&ccb=7-5&ig_cache_key=MzgxOTQ5NjUzNTA2NzU3Mjg5MQ%3D%3D.3-ccb7-5&oh=00_AfyVZLBXSkhlRPXmASWStRsBLABr9g6561BlECRuhTc4jQ&oe=69BD8881&_nc_sid=8b3546, https://scontent-phl2-1.cdninstagram.com/v/t51.82787-15/605709807_18067465175417012_6147621685105692945_n.webp?stp=dst-jpg_e35_s1080x1080_sh0.08_tt6&_nc_ht=scontent-phl2-1.cdninstagram.com&_nc_cat=108&_nc_oc=Q6cZ2QFPWgNUb1KpcUUyXr4ds-2fIkhkHYd08XdLrBtvUKiX5WEtS6FVKMdUJCwbFCV3xCEfHlpcQYB_FSv18iWqwT6Y&_nc_ohc=TidaMP0OMkoQ7kNvwFUBQN1&_nc_gid=1pFHKT8-V7u_uRgJew64Sw&edm=AOQ1c0wBAAAA&ccb=7-5&ig_cache_key=Mzc5NDMwNTAyNTY3ODUzMTk4OQ%3D%3D.3-ccb7-5&oh=00_AfxKVPt0HDSVC83SqMRyKrUNuo6E1J7mvqH4KRLZY8CzPQ&oe=69BD949A&_nc_sid=8b3546, https://scontent-phl2-1.cdninstagram.com/v/t51.82787-15/591571878_18066621008417012_4456102103001143751_n.webp?stp=dst-jpg_e35_s1080x1080_sh0.08_tt6&_nc_ht=scontent-phl2-1.cdninstagram.com&_nc_cat=108&_nc_oc=Q6cZ2QFPWgNUb1KpcUUyXr4ds-2fIkhkHYd08XdLrBtvUKiX5WEtS6FVKMdUJCwbFCV3xCEfHlpcQYB_FSv18iWqwT6Y&_nc_ohc=afcyM3T04PsQ7kNvwHi95Ev&_nc_gid=1pFHKT8-V7u_uRgJew64Sw&edm=AOQ1c0wBAAAA&ccb=7-5&ig_cache_key=Mzc4NzQ5NTU0NDgwNjUwODA4OQ%3D%3D.3-ccb7-5&oh=00_Afz4f9CfiJQso1RDz2LVcjo9gOCsAyCdqlmlwfSDbK0d-Q&oe=69BDA8BF&_nc_sid=8b3546, https://scontent-phl2-1.cdninstagram.com/v/t51.82787-15/590362270_18066045839417012_1317985682267789910_n.webp?stp=dst-jpg_e35_s1080x1080_sh0.08_tt6&_nc_ht=scontent-phl2-1.cdninstagram.com&_nc_cat=108&_nc_oc=Q6cZ2QFPWgNUb1KpcUUyXr4ds-2fIkhkHYd08XdLrBtvUKiX5WEtS6FVKMdUJCwbFCV3xCEfHlpcQYB_FSv18iWqwT6Y&_nc_ohc=67LFTq1dpRsQ7kNvwH__Zhl&_nc_gid=1pFHKT8-V7u_uRgJew64Sw&edm=AOQ1c0wBAAAA&ccb=7-5&ig_cache_key=Mzc4MzEyMzIwNzg2ODcxMjU4MQ%3D%3D.3-ccb7-5&oh=00_AfzswaFG_BZwVcwp335AwjBncIBePH6C_yXAyeEjYuhC7Q&oe=69BD834F&_nc_sid=8b3546, https://scontent-phl2-1.cdninstagram.com/v/t51.82787-15/591164059_18065984405417012_2561544330395023426_n.webp?stp=dst-jpg_e35_s1080x1080_sh0.08_tt6&_nc_ht=scontent-phl2-1.cdninstagram.com&_nc_cat=108&_nc_oc=Q6cZ2QFPWgNUb1KpcUUyXr4ds-2fIkhkHYd08XdLrBtvUKiX5WEtS6FVKMdUJCwbFCV3xCEfHlpcQYB_FSv18iWqwT6Y&_nc_ohc=JYVQditDp3UQ7kNvwEjf-qC&_nc_gid=1pFHKT8-V7u_uRgJew64Sw&edm=AOQ1c0wBAAAA&ccb=7-5&ig_cache_key=Mzc4MjcyNTgyMTYzOTk4NjgxMw%3D%3D.3-ccb7-5&oh=00_Afwq2dh9GBs-sWkDJ_GkjjEeBNyquX05tA5MoiVTh__YLA&oe=69BD9B34&_nc_sid=8b3546, https://scontent-phl2-1.cdninstagram.com/v/t51.82787-15/584366518_18064435880417012_6105331510785573369_n.webp?stp=dst-jpg_e35_s1080x1080_sh0.08_tt6&_nc_ht=scontent-phl2-1.cdninstagram.com&_nc_cat=108&_nc_oc=Q6cZ2QFPWgNUb1KpcUUyXr4ds-2fIkhkHYd08XdLrBtvUKiX5WEtS6FVKMdUJCwbFCV3xCEfHlpcQYB_FSv18iWqwT6Y&_nc_ohc=GyRhJgJNvRkQ7kNvwGJJVvB&_nc_gid=1pFHKT8-V7u_uRgJew64Sw&edm=AOQ1c0wBAAAA&ccb=7-5&ig_cache_key=Mzc3MDU0MDA1NDM0MzkxNzU2OQ%3D%3D.3-ccb7-5&oh=00_Afyw9PvqFQdzX5bi6vYifnFdvE9hn4zboi-RZ6YDeIV9OA&oe=69BDAB59&_nc_sid=8b3546 | Z6: https://scontent-phl2-1.cdninstagram.com/o1/v/t16/f2/m69/AQOLrX_DzFYXvdtnGa82YIH8Z5Yyf4hEvUt9q1XNybgd92u1oLTjrAeiS-rFiwO2ln_eFBStixihybqCdfL_Fwfh.mp4?strext=1&_nc_cat=108&_nc_sid=5e9851&_nc_ht=scontent-phl2-1.cdninstagram.com&_nc_ohc=XpaHJa3CupgQ7kNvwFBqXLo&efg=eyJ2ZW5jb2RlX3RhZyI6Inhwdl9wcm9ncmVzc2l2ZS5JTlNUQUdSQU0uQ0xJUFMuQzMuNzIwLmRhc2hfYmFzZWxpbmVfMV92MSIsInhwdl9hc3NldF9pZCI6MTgwNzUxMjQ2NzY0MTcwMTIsImFzc2V0X2FnZV9kYXlzIjoyLCJ2aV91c2VjYXNlX2lkIjoxMDA5OSwiZHVyYXRpb25fcyI6NSwidXJsZ2VuX3NvdXJjZSI6Ind3dyJ9&ccb=17-1&_nc_gid=1pFHKT8-V7u_uRgJew64Sw&_nc_ss=1a&_nc_zt=28&vs=c2cb3f12a3817c86&_nc_vs=HBkcFQIYOnBhc3N0aHJvdWdoX2V2ZXJzdG9yZS9HQ3Rqb0Nid1dUeXZ3TFFDQU5jZlR3ZE5LUmhBYnNwVEFRQUYVAALIARIAKAAYABsCiAd1c2Vfb2lsATEScHJvZ3Jlc3NpdmVfcmVjaXBlATEVAAAm6Nfemd3Om0AVAigCQzMsF0AUIcrAgxJvGBJkYXNoX2Jhc2VsaW5lXzFfdjERAHX-B2XmnQEA&oh=00_AfyPx1ZSenBHy5AaEZR38O0rYARKD727MtG-KUZ_ic1LCw&oe=69BDB994, https://scontent-phl2-1.cdninstagram.com/o1/v/t16/f2/m69/AQMAV2ctX29sKSeIQZpKQG3Ctgv-yfCdnExg24ihnMlCOVAa-ngSq4prG6-Fji3oPhGrUngN4cfqICHsBd3t77aH.mp4?strext=1&_nc_cat=107&_nc_sid=5e9851&_nc_ht=scontent-phl2-1.cdninstagram.com&_nc_ohc=Cvemj7HwIHkQ7kNvwE_6FRY&efg=eyJ2ZW5jb2RlX3RhZyI6Inhwdl9wcm9ncmVzc2l2ZS5JTlNUQUdSQU0uQ0xJUFMuQzMuNzIwLmRhc2hfYmFzZWxpbmVfMV92MSIsInhwdl9hc3NldF9pZCI6MTgwNzUxMjQyMTQ0MTcwMTIsImFzc2V0X2FnZV9kYXlzIjoyLCJ2aV91c2VjYXNlX2lkIjoxMDA5OSwiZHVyYXRpb25fcyI6NSwidXJsZ2VuX3NvdXJjZSI6Ind3dyJ9&ccb=17-1&_nc_gid=1pFHKT8-V7u_uRgJew64Sw&_nc_ss=1a&_nc_zt=28&vs=2fde5ed498b16528&_nc_vs=HBkcFQIYOnBhc3N0aHJvdWdoX2V2ZXJzdG9yZS9HRFk1cENiYmtwUm94d2dGQUlqdVVFdlF2M0FIYnNwVEFRQUYVAALIARIAKAAYABsCiAd1c2Vfb2lsATEScHJvZ3Jlc3NpdmVfcmVjaXBlATEVAAAm6JmS4dnOm0AVAigCQzMsF0AUIcrAgxJvGBJkYXNoX2Jhc2VsaW5lXzFfdjERAHX-B2XmnQEA&oh=00_Afx3fNwKEy2CG2l0og5g2IFIiyQk9ngXc8OvLuwh3y0-8Q&oe=69BD94FD, https://scontent-phl2-1.cdninstagram.com/o1/v/t16/f2/m69/AQMLbx7VysntC_VPg9hPEpNToyCID-m9mvPMwW7DQcyLb4T7uwnoY9auvBjPZ0kqIM6OED_DiiD8AYk4DXnmQl9N.mp4?strext=1&_nc_cat=111&_nc_sid=5e9851&_nc_ht=scontent-phl2-1.cdninstagram.com&_nc_ohc=S7OsF6E5rqYQ7kNvwFjZQyI&efg=eyJ2ZW5jb2RlX3RhZyI6Inhwdl9wcm9ncmVzc2l2ZS5JTlNUQUdSQU0uQ0xJUFMuQzMuNzIwLmRhc2hfYmFzZWxpbmVfMV92MSIsInhwdl9hc3NldF9pZCI6MTgwNzUxMjMzOTg0MTcwMTIsImFzc2V0X2FnZV9kYXlzIjoyLCJ2aV91c2VjYXNlX2lkIjoxMDA5OSwiZHVyYXRpb25fcyI6NSwidXJsZ2VuX3NvdXJjZSI6Ind3dyJ9&ccb=17-1&_nc_gid=1pFHKT8-V7u_uRgJew64Sw&_nc_ss=1a&_nc_zt=28&vs=824d553fa2ab5a3e&_nc_vs=HBkcFQIYOnBhc3N0aHJvdWdoX2V2ZXJzdG9yZS9HQWFFdmliQ2Z0ZkVHT0lEQU03VEhFZC1kcjFvYnNwVEFRQUYVAALIARIAKAAYABsCiAd1c2Vfb2lsATEScHJvZ3Jlc3NpdmVfcmVjaXBlATEVAAAm6On41tPOm0AVAigCQzMsF0AUIcrAgxJvGBJkYXNoX2Jhc2VsaW5lXzFfdjERAHX-B2XmnQEA&oh=00_AfxYxna72tbr-SfNeo-3HDPhXtl3mNnydDY5li3RII5MLg&oe=69BD8F21, https://scontent-phl2-1.cdninstagram.com/o1/v/t16/f2/m69/AQNHgx1viqChHfbgG-jq44QRjuZa2sBhRQhvq1K9O5KHFveNPQi4eQIiQ9LOH6EEIlKX5STgPBXX1SlzUnbeDDGx.mp4?strext=1&_nc_cat=107&_nc_sid=5e9851&_nc_ht=scontent-phl2-1.cdninstagram.com&_nc_ohc=9v1HjNLk-UwQ7kNvwERWd_V&efg=eyJ2ZW5jb2RlX3RhZyI6Inhwdl9wcm9ncmVzc2l2ZS5JTlNUQUdSQU0uQ0xJUFMuQzMuNzIwLmRhc2hfYmFzZWxpbmVfMV92MSIsInhwdl9hc3NldF9pZCI6MTgwNzUxMjI2NzU0MTcwMTIsImFzc2V0X2FnZV9kYXlzIjoyLCJ2aV91c2VjYXNlX2lkIjoxMDA5OSwiZHVyYXRpb25fcyI6NSwidXJsZ2VuX3NvdXJjZSI6Ind3dyJ9&ccb=17-1&_nc_gid=1pFHKT8-V7u_uRgJew64Sw&_nc_ss=1a&_nc_zt=28&vs=7ed5900c0f091787&_nc_vs=HBkcFQIYOnBhc3N0aHJvdWdoX2V2ZXJzdG9yZS9HS3VtdHliOHRwVGpEVXdEQUVuSG5MRUZRamRTYnNwVEFRQUYVAALIARIAKAAYABsCiAd1c2Vfb2lsATEScHJvZ3Jlc3NpdmVfcmVjaXBlATEVAAAm6P63pc7Om0AVAigCQzMsF0AUIcrAgxJvGBJkYXNoX2Jhc2VsaW5lXzFfdjERAHX-B2XmnQEA&oh=00_AfwLm9NMnX7zXhDPY5qXdXfU-WtoTIZlz8VPdjTZIzbicw&oe=69BDB321, https://scontent-phl2-1.cdninstagram.com/o1/v/t16/f2/m69/AQMADcVlBs31O_whCMjSgpTnE1l4FGNubYJZcooTYQ6iBnZvvG7u37mzizKGHHLawx3YI3meoiZ2BVVExTdKbRMZ.mp4?strext=1&_nc_cat=100&_nc_sid=5e9851&_nc_ht=scontent-phl2-1.cdninstagram.com&_nc_ohc=MCmBy5LxA3oQ7kNvwEmI4NE&efg=eyJ2ZW5jb2RlX3RhZyI6Inhwdl9wcm9ncmVzc2l2ZS5JTlNUQUdSQU0uQ0xJUFMuQzMuNzE2LmRhc2hfYmFzZWxpbmVfMV92MSIsInhwdl9hc3NldF9pZCI6MTgwNzUxMjIzNDU0MTcwMTIsImFzc2V0X2FnZV9kYXlzIjoyLCJ2aV91c2VjYXNlX2lkIjoxMDA5OSwiZHVyYXRpb25fcyI6NSwidXJsZ2VuX3NvdXJjZSI6Ind3dyJ9&ccb=17-1&_nc_gid=1pFHKT8-V7u_uRgJew64Sw&_nc_ss=1a&_nc_zt=28&vs=47f892d7476196f9&_nc_vs=HBkcFQIYOnBhc3N0aHJvdWdoX2V2ZXJzdG9yZS9HTllXMENiN0JacURMYk1FQURyVFRUMXp3b3BoYnNwVEFRQUYVAALIARIAKAAYABsCiAd1c2Vfb2lsATEScHJvZ3Jlc3NpdmVfcmVjaXBlATEVAAAm6OTc6svOm0AVAigCQzMsF0AUIcrAgxJvGBJkYXNoX2Jhc2VsaW5lXzFfdjERAHX-B2XmnQEA&oh=00_AfxDF1bKZ0IYmH8Jda1rTKqjGYagUGE6wOIvjFdX1SCz9g&oe=69BD9594 | AA6: 8 | AB6: 0 | AC6: 46097 | AD6: loupethis | AE6: collector_page | AF6: https://www.instagram.com/gustavo_lopes_imagens
